
Traceback (most recent call last):
  File "tests/exceptions/source/backtrace/nested_explicit_catch_up.py", line 19, in <module>
    foo()
  File "tests/exceptions/source/backtrace/nested_explicit_catch_up.py", line 10, in foo
    bar()
  File "tests/exceptions/source/backtrace/nested_explicit_catch_up.py", line 15, in bar
    1 / 0
ZeroDivisionError: division by zero

Traceback (most recent call last):
> File "tests/exceptions/source/backtrace/nested_explicit_catch_up.py", line 19, in <module>
    foo()
  File "tests/exceptions/source/backtrace/nested_explicit_catch_up.py", line 10, in foo
    bar()
  File "tests/exceptions/source/backtrace/nested_explicit_catch_up.py", line 15, in bar
    1 / 0
ZeroDivisionError: division by zero
